<?xml version='1.0' encoding='utf-8'?>
<mujoco model="robotiq_2f85">
  <compiler angle="radian" meshdir="assets" autolimits="true" />
  <include file="scene.xml" />
  <option solver="Newton" tolerance="1e-6" timestep="1e-04" integrator="RK4" gravity="0 0 -9.81" />
  <asset>
    <material name="metal" rgba="0.58 0.58 0.58 1" />
    <material name="silicone" rgba="0.1882 0.1882 0.1882 1" />
    <material name="gray" rgba="0.4627 0.4627 0.4627 1" />
    <material name="black" rgba="0.149 0.149 0.149 1" />
    <material name="red" rgba="1 0.149 0.149 1" />
    <mesh class="2f85" file="base_mount.stl" />
    <mesh class="2f85" file="base.stl" />
    <mesh class="2f85" file="driver.stl" />
    <mesh class="2f85" file="coupler.stl" />
    <mesh class="2f85" file="follower.stl" />
    <mesh class="2f85" file="pad.stl" />
    <mesh class="2f85" file="silicone_pad.stl" />
    <mesh class="2f85" file="spring_link.stl" />
    <mesh name="tazza" file="tazza.stl" scale="0.001 0.001 0.001" />
    <material name="sphere_material_0" rgba="1 0 0 1" />
    <material name="sphere_material_1" rgba="0 1 0 1" />
    <material name="sphere_material_2" rgba="0 0 1 1" />
    <material name="sphere_material_3" rgba="1 1 0 1" />
    <material name="sphere_material_4" rgba="1 0 1 1" />
    <material name="sphere_material_5" rgba="0 1 1 1" />
    <material name="sphere_material_6" rgba="1 0.5 0 1" />
    <material name="sphere_material_7" rgba="0.5 0 1 1" />
    <material name="sphere_material_8" rgba="1 0.75 0.8 1" />
    <material name="sphere_material_9" rgba="0.5 0.5 0.5 1" />
  </asset>
  <default>
    <default class="2f85">
      <mesh scale="0.001 0.001 0.001" />
      <general biastype="affine" />
      <joint axis="1 0 0" />
      <default class="driver">
        <joint range="0 0.8" armature="0.005" damping="0.1" solimplimit="0.95 0.99 0.001" solreflimit="0.005 1" />
      </default>
      <default class="follower">
        <joint range="-0.872664 0.872664" armature="0.001" pos="0 -0.018 0.0065" solimplimit="0.95 0.99 0.001" solreflimit="0.005 1" />
      </default>
      <default class="spring_link">
        <joint range="-0.29670597283 0.8" armature="0.001" stiffness="0.05" springref="2.62" damping="0.00125" />
      </default>
      <default class="coupler">
        <joint range="-1.57 0" armature="0.001" solimplimit="0.95 0.99 0.001" solreflimit="0.005 1" />
      </default>
      <default class="visual">
        <geom type="mesh" contype="0" conaffinity="0" group="2" />
      </default>
      <default class="collision">
        <geom type="mesh" group="3" />
        <default class="pad_box1">
          <geom mass="0" type="box" pos="0 -0.0026 0.028125" size="0.011 0.004 0.009375" friction="0.7" solimp="0.95 0.99 0.001" solref="0.004 1" priority="1" rgba="0.55 0.55 0.55 1" />
        </default>
        <default class="pad_box2">
          <geom mass="0" type="box" pos="0 -0.0026 0.009375" size="0.011 0.004 0.009375" friction="0.6" solimp="0.95 0.99 0.001" solref="0.004 1" priority="1" rgba="0.45 0.45 0.45 1" />
        </default>
      </default>
    </default>
  </default>
  <worldbody>
    <body name="base_mount" pos="0 0 0.18" quat="0 1 0 0" childclass="2f85">
      <joint name="indenter_slider" type="slide" axis="0 0 -1" range="0 0.1" damping="100" stiffness="10" />
      <geom class="visual" mesh="base_mount" material="black" />
      <geom class="collision" mesh="base_mount" />
      <body name="base" pos="0 0 0.0038" quat="1 0 0 -1">
        <inertial mass="0.777441" pos="0 -2.70394e-05 0.0354675" quat="1 -0.00152849 0 0" diaginertia="0.000260285 0.000225381 0.000152708" />
        <geom class="visual" mesh="base" material="black" />
        <geom class="collision" mesh="base" />
        <site name="pinch" pos="0 0 0.145" type="sphere" group="5" rgba="0.9 0.9 0.9 1" size="0.005" />
        <body name="right_driver" pos="0 0.0306011 0.054904">
          <inertial mass="0.00899563" pos="2.96931e-12 0.0177547 0.00107314" quat="0.681301 0.732003 0 0" diaginertia="1.72352e-06 1.60906e-06 3.22006e-07" />
          <joint name="right_driver_joint" class="driver" />
          <geom class="visual" mesh="driver" material="gray" />
          <geom class="collision" mesh="driver" />
          <body name="right_coupler" pos="0 0.0315 -0.0041">
            <inertial mass="0.0140974" pos="0 0.00301209 0.0232175" quat="0.705636 -0.0455904 0.0455904 0.705636" diaginertia="4.16206e-06 3.52216e-06 8.88131e-07" />
            <joint name="right_coupler_joint" class="coupler" />
            <geom class="visual" mesh="coupler" material="black" />
            <geom class="collision" mesh="coupler" />
          </body>
        </body>
        <body name="right_spring_link" pos="0 0.0132 0.0609">
          <inertial mass="0.0221642" pos="-8.65005e-09 0.0181624 0.0212658" quat="0.663403 -0.244737 0.244737 0.663403" diaginertia="8.96853e-06 6.71733e-06 2.63931e-06" />
          <joint name="right_spring_link_joint" class="spring_link" />
          <geom class="visual" mesh="spring_link" material="black" />
          <geom class="collision" mesh="spring_link" />
          <body name="right_follower" pos="0 0.055 0.0375">
            <inertial mass="0.0125222" pos="0 -0.011046 0.0124786" quat="1 0.1664 0 0" diaginertia="2.67415e-06 2.4559e-06 6.02031e-07" />
            <joint name="right_follower_joint" class="follower" />
            <geom class="visual" mesh="follower" material="black" />
            <geom class="collision" mesh="follower" />
            <body name="right_pad" pos="0 -0.0189 0.01352">
              <geom class="pad_box1" name="right_pad1" />
              <geom class="pad_box2" name="right_pad2" />
              <inertial mass="0.0035" pos="0 -0.0025 0.0185" quat="0.707107 0 0 0.707107" diaginertia="4.73958e-07 3.64583e-07 1.23958e-07" />
              <geom class="visual" mesh="pad" />
              <body name="right_silicone_pad">
                <geom class="visual" mesh="silicone_pad" material="black" />
                <flexcomp name="Elas_A" type="grid" count="8 4 2" spacing=".004 .004 .004" pos="0 -0.01 0.02" euler="1.57 0 1.57" radius=".0005" rgba="0 .7 .7 1" dim="3" mass="4e-2">
                  <pin id="0  2  4  6  8  10  12  14  16  18  20  22  24  26  28  30  32  34  36  38  40  42  44  46  48  50  52  54  56  58  60  62" />
                  <contact condim="3" solref="0.01 1" solimp=".95 .99 .0001" selfcollide="none" />
                  <edge damping="1" />
                  <elasticity young="1e5" poisson="0" />
                </flexcomp>
              </body>
            </body>
          </body>
        </body>
        <body name="left_driver" pos="0 -0.0306011 0.054904" quat="0 0 0 1">
          <inertial mass="0.00899563" pos="0 0.0177547 0.00107314" quat="0.681301 0.732003 0 0" diaginertia="1.72352e-06 1.60906e-06 3.22006e-07" />
          <joint name="left_driver_joint" class="driver" />
          <geom class="visual" mesh="driver" material="gray" />
          <geom class="collision" mesh="driver" />
          <body name="left_coupler" pos="0 0.0315 -0.0041">
            <inertial mass="0.0140974" pos="0 0.00301209 0.0232175" quat="0.705636 -0.0455904 0.0455904 0.705636" diaginertia="4.16206e-06 3.52216e-06 8.88131e-07" />
            <joint name="left_coupler_joint" class="coupler" />
            <geom class="visual" mesh="coupler" material="black" />
            <geom class="collision" mesh="coupler" />
          </body>
        </body>
        <body name="left_spring_link" pos="0 -0.0132 0.0609" quat="0 0 0 1">
          <inertial mass="0.0221642" pos="-8.65005e-09 0.0181624 0.0212658" quat="0.663403 -0.244737 0.244737 0.663403" diaginertia="8.96853e-06 6.71733e-06 2.63931e-06" />
          <joint name="left_spring_link_joint" class="spring_link" />
          <geom class="visual" mesh="spring_link" material="black" />
          <geom class="collision" mesh="spring_link" />
          <body name="left_follower" pos="0 0.055 0.0375">
            <inertial mass="0.0125222" pos="0 -0.011046 0.0124786" quat="1 0.1664 0 0" diaginertia="2.67415e-06 2.4559e-06 6.02031e-07" />
            <joint name="left_follower_joint" class="follower" />
            <geom class="visual" mesh="follower" material="black" />
            <geom class="collision" mesh="follower" />
            <body name="left_pad" pos="0 -0.0189 0.01352">
              <geom class="pad_box1" name="left_pad1" />
              <geom class="pad_box2" name="left_pad2" />
              <inertial mass="0.0035" pos="0 -0.0025 0.0185" quat="1 0 0 1" diaginertia="4.73958e-07 3.64583e-07 1.23958e-07" />
              <geom class="visual" mesh="pad" />
              <body name="left_silicone_pad">
                <geom class="visual" mesh="silicone_pad" material="black" />
                <flexcomp name="Elas_B" type="grid" count="8 4 2" spacing=".004 .004 .004" pos="0 -0.01 0.02" euler="1.57 0 1.57" radius=".0005" rgba="0 .7 .7 1" dim="3" mass="4e-2">
                  <pin id="0  2  4  6  8  10  12  14  16  18  20  22  24  26  28  30  32  34  36  38  40  42  44  46  48  50  52  54  56  58  60  62" />
                  <contact condim="3" solref="0.01 1" solimp=".95 .99 .0001" selfcollide="none" />
                  <edge damping="1" />
                  <elasticity young="1e5" poisson="0" />
                </flexcomp>
              </body>
            </body>
          </body>
        </body>
      </body>
    </body>
    <body name="power_button" pos="0 0 0" quat="0.7071 0 0 0.7071">
      <freejoint />
      <geom type="mesh" mesh="tazza" pos="-0.046 -0.03 0 " rgba="0.6 0.6 0.1 0.3" group="1" contype="0" conaffinity="0" />
      <geom type="cylinder" size="0.03 0.002" pos="0 0 0.002" rgba="1 0 0 0" />
      <geom type="box" size="0.03 0.001 0.02" pos="0 0.02 0.02" rgba="1 0 0 0" />
      <geom type="box" size="0.03 0.001 0.02" pos="0 -0.02 0.02" rgba="1 0 0 0" />
      <geom type="box" size="0.001 0.03 0.02" pos="0.02 0 0.02" rgba="1 0 0 0" />
      <geom type="box" size="0.001 0.03 0.02" pos="-0.02 0 0.02" rgba="1 0 0 0" />
    </body>
    <body name="sphere_1" pos="0.005710 -0.002573 0.031319">
      <freejoint />
      <geom type="sphere" size="0.008" material="sphere_material_0" />
    </body>
    <body name="sphere_2" pos="-0.001130 0.003238 0.031322">
      <freejoint />
      <geom type="sphere" size="0.008" material="sphere_material_1" />
    </body>
    <body name="sphere_3" pos="0.002333 -0.000775 0.030737">
      <freejoint />
      <geom type="sphere" size="0.008" material="sphere_material_2" />
    </body>
    <body name="sphere_4" pos="0.005178 -0.009960 0.039015">
      <freejoint />
      <geom type="sphere" size="0.008" material="sphere_material_3" />
    </body>
    <body name="sphere_5" pos="0.006288 -0.004265 0.031357">
      <freejoint />
      <geom type="sphere" size="0.008" material="sphere_material_4" />
    </body>
    <body name="sphere_6" pos="0.004946 -0.005050 0.033485">
      <freejoint />
      <geom type="sphere" size="0.008" material="sphere_material_5" />
    </body>
    <body name="sphere_7" pos="0.008729 -0.000275 0.033142">
      <freejoint />
      <geom type="sphere" size="0.008" material="sphere_material_6" />
    </body>
    <body name="sphere_8" pos="-0.007448 -0.004123 0.031524">
      <freejoint />
      <geom type="sphere" size="0.008" material="sphere_material_7" />
    </body>
    <body name="sphere_9" pos="-0.009051 0.009724 0.030879">
      <freejoint />
      <geom type="sphere" size="0.008" material="sphere_material_8" />
    </body>
    <body name="sphere_10" pos="-0.008733 -0.005035 0.036806">
      <freejoint />
      <geom type="sphere" size="0.008" material="sphere_material_9" />
    </body>
    <body name="sphere_11" pos="-0.006643 -0.008365 0.037936">
      <freejoint />
      <geom type="sphere" size="0.008" material="sphere_material_0" />
    </body>
    <body name="sphere_12" pos="0.004759 0.003047 0.031512">
      <freejoint />
      <geom type="sphere" size="0.008" material="sphere_material_1" />
    </body>
    <body name="sphere_13" pos="0.007042 0.005946 0.039683">
      <freejoint />
      <geom type="sphere" size="0.008" material="sphere_material_2" />
    </body>
    <body name="sphere_14" pos="0.006800 0.008881 0.039600">
      <freejoint />
      <geom type="sphere" size="0.008" material="sphere_material_3" />
    </body>
    <body name="sphere_15" pos="-0.000571 0.000545 0.038958">
      <freejoint />
      <geom type="sphere" size="0.008" material="sphere_material_4" />
    </body>
    <body name="sphere_16" pos="-0.002440 0.000182 0.032158">
      <freejoint />
      <geom type="sphere" size="0.008" material="sphere_material_5" />
    </body>
    <body name="sphere_17" pos="0.009904 -0.009469 0.032148">
      <freejoint />
      <geom type="sphere" size="0.008" material="sphere_material_6" />
    </body>
    <body name="sphere_18" pos="-0.005747 -0.004644 0.033334">
      <freejoint />
      <geom type="sphere" size="0.008" material="sphere_material_7" />
    </body>
    <body name="sphere_19" pos="-0.001329 0.007831 0.030020">
      <freejoint />
      <geom type="sphere" size="0.008" material="sphere_material_8" />
    </body>
    <body name="sphere_20" pos="0.009771 -0.009125 0.031146">
      <freejoint />
      <geom type="sphere" size="0.008" material="sphere_material_9" />
    </body>
  </worldbody>
  <contact>
    <exclude body1="base" body2="left_driver" />
    <exclude body1="base" body2="right_driver" />
    <exclude body1="base" body2="left_spring_link" />
    <exclude body1="base" body2="right_spring_link" />
    <exclude body1="right_coupler" body2="right_follower" />
    <exclude body1="left_coupler" body2="left_follower" />
  </contact>
  <tendon>
    <fixed name="split">
      <joint joint="right_driver_joint" coef="0.5" />
      <joint joint="left_driver_joint" coef="0.5" />
    </fixed>
  </tendon>
  <equality>
    <connect anchor="0 0 0" body1="right_follower" body2="right_coupler" solimp="0.95 0.99 0.001" solref="0.005 1" />
    <connect anchor="0 0 0" body1="left_follower" body2="left_coupler" solimp="0.95 0.99 0.001" solref="0.005 1" />
    <joint joint1="right_driver_joint" joint2="left_driver_joint" polycoef="0 1 0 0 0" solimp="0.95 0.99 0.001" solref="0.005 1" />
  </equality>
  <actuator>
    <general class="2f85" name="fingers_actuator" tendon="split" forcerange="-50 50" ctrlrange="0 255" gainprm="0.3137255 0 0" biasprm="0 -100 -10" />
    <position name="position_control" joint="indenter_slider" kp="500" kv="10" ctrlrange="0.0 0.1" />
  </actuator>
</mujoco>
