
    <mujoco model="Press">
        <include file="scene.xml" />
        <compiler autolimits="true" />
        <option solver="Newton" tolerance="1e-8" timestep="1e-05" 
           integrator="implicitfast"/>
        <size memory="100M" />
        <asset>
            <mesh file="./CNC3018.STL" name="CNC3018" scale="0.001 0.001 0.001" />
            <mesh file="./board.STL" name="board" scale="0.001 0.001 0.001" />
            <mesh file="./rig.STL" name="rig" scale="0.001 0.001 0.001" />
            <mesh file="./indenter_type2.STL" name="indenter" scale="0.001 0.001 0.001" />
            <mesh file="./press_sensor.STL" name="press_sensor" scale="0.001 0.001 0.001" />
            <mesh file="./press_outer.STL" name="press_outer" scale="0.001 0.001 0.001" />
        </asset>
        <worldbody>
            <body name="cnc3018" pos="-0.1948 -0.1628 0" euler="0 0 0">
            <geom type="mesh" mesh="CNC3018" name="cnc3018_geom" rgba="0.1 0.1 0.1 1" contype="0" conaffinity="0"/>
            <body name="board" pos="0.04 0.27 0.06" quat="0.717 0.717 0 0">
                <geom type="mesh" mesh="board" name="board_geom" rgba="0.4 0.4 0.4 1" contype="0" conaffinity="0"/>
                <body name="rig" pos="0.121 0.0270 0.0735" quat="0.717 0.717 0 0">
                    <geom type="mesh" mesh="rig" name="rig_geom" rgba="1 1 1 1" contype="0" conaffinity="0"/>
                        <body name="pcb" pos="0.034 0.034 0.0016">
                            <geom name="pcb_geom" type="box" size="0.008 0.008 0.0008" rgba="0.1 0.4 0.1 1" contype="0" conaffinity="0"/>
                        </body>
                </body>
            </body>
        </body>
            <flexcomp name="A" type="grid" count="17 17 4" 
                spacing="0.001 0.001 0.001" 
                pos="0 0 0.0875"
                radius=".0005" rgba="0 1 1 0.7" dim="3" mass="0.003993600000000001">
                <pin id="0 4 8 12 16 20 24 28 32 36 40 44 48 52 56 60 64 68 72 76 80 84 88 92 96 100 104 108 112 116 120 124 128 132 136 140 144 148 152 156 160 164 168 172 176 180 184 188 192 196 200 204 208 212 216 220 224 228 232 236 240 244 248 252 256 260 264 268 272 276 280 284 288 292 296 300 304 308 312 316 320 324 328 332 336 340 344 348 352 356 360 364 368 372 376 380 384 388 392 396 400 404 408 412 416 420 424 428 432 436 440 444 448 452 456 460 464 468 472 476 480 484 488 492 496 500 504 508 512 516 520 524 528 532 536 540 544 548 552 556 560 564 568 572 576 580 584 588 592 596 600 604 608 612 616 620 624 628 632 636 640 644 648 652 656 660 664 668 672 676 680 684 688 692 696 700 704 708 712 716 720 724 728 732 736 740 744 748 752 756 760 764 768 772 776 780 784 788 792 796 800 804 808 812 816 820 824 828 832 836 840 844 848 852 856 860 864 868 872 876 880 884 888 892 896 900 904 908 912 916 920 924 928 932 936 940 944 948 952 956 960 964 968 972 976 980 984 988 992 996 1000 1004 1008 1012 1016 1020 1024 1028 1032 1036 1040 1044 1048 1052 1056 1060 1064 1068 1072 1076 1080 1084 1088 1092 1096 1100 1104 1108 1112 1116 1120 1124 1128 1132 1136 1140 1144 1148 1152" />
                 <contact condim="6" selfcollide="none" solref="0.001 0.9"
                    solimp="0.99999 0.99999 0.001 0.99999 1"/>
                <edge damping="1e-1" />
                <elasticity young="1.2e5" poisson="0.49" damping="1e-6"/>
            </flexcomp>
            <body name="indenter" pos="-0.006 -0.006 0.118" quat="0 1 0 0">
                <joint name="indenter_slider" type="slide" axis="0 0 1" range="0 0.009"
                    damping="1" stiffness="0" />
                <geom type="mesh" mesh="indenter"  pos="-0.0173 0.0173 0" quat="0.717 0.717 0 0" name="indenter_geom" rgba="0.8 0.3 0.3 1"  solref="0.001 0.9"/>
                <site name="force_sensor_site" type="sphere" size="0.0005" pos="0 0 0.005"
                    rgba="1 0 0 1" />
                <body name="outer" pos="0 0 0" quat="0 0 0 1">
                    <geom type="mesh" mesh="press_outer" name="press_outer_geom" pos="-0.022 0.022 -0.05" quat="0.717 0.717 0 0" rgba="0.4 0.4 0.4 1" />
                </body>
            </body>
        </worldbody>
        <actuator>
            <position name="position_control" joint="indenter_slider" kp="500000" kv="1000" ctrlrange="0.0 0.009"/>
        </actuator>
        <sensor>
            <force name="force_sensor" site="force_sensor_site" />
            <actuatorfrc name="actuator_force" actuator="position_control"/>
            <jointpos name="indenter_position" joint="indenter_slider"/>
            <jointvel name="indenter_velocity" joint="indenter_slider"/>
        </sensor>

    </mujoco>
    